Workbook

Sheet Margin Model
A1: Vantage Meridian — Internal Margin Model
A2: CONFIDENTIAL — internal only. Pay rates and multiplier must not be shared with clients or the team.
A4: Standard charge-out multiplier | B4: 1.6 | C4: Covers insurances, unbillable principal time, tendering cost and commercial risk (no seed capital).
A6: Role | B6: Head-count | C6: Candidate ask ($/day) | D6: Pay rate ($/day) | E6: Multiplier | F6: Charge-out ($/day) | G6: Gross margin ($/day) | H6: Margin % | I6: QLD market low ($/day) | J6: QLD market high ($/day) | K6: Position vs market
A7: Developer — Junior | B7: 0 | D7: 550 | E7: =$B$4 | F7: =D7*E7 | G7: =F7-D7 | H7: =IF(F7=0,0,G7/F7) | I7: 400 | J7: 810 | K7: =IF(F7>J7*1.15,"Above market ceiling",IF(F7>J7,"Top of market","Within market"))
A8: Developer — Mid (Frontend / CRM / Backend) | B8: 2 | D8: 700 | E8: =$B$4 | F8: =D8*E8 | G8: =F8-D8 | H8: =IF(F8=0,0,G8/F8) | I8: 665 | J8: 905 | K8: =IF(F8>J8*1.15,"Above market ceiling",IF(F8>J8,"Top of market","Within market"))
A9: Developer — Senior | B9: 1 | D9: 850 | E9: =$B$4 | F9: =D9*E9 | G9: =F9-D9 | H9: =IF(F9=0,0,G9/F9) | I9: 760 | J9: 1235 | K9: =IF(F9>J9*1.15,"Above market ceiling",IF(F9>J9,"Top of market","Within market"))
A10: Business Analyst | B10: 1 | C10: 1100 | D10: 1000 | E10: 1.4 | F10: =D10*E10 | G10: =F10-D10 | H10: =IF(F10=0,0,G10/F10) | I10: 900 | J10: 1215 | K10: =IF(F10>J10*1.15,"Above market ceiling",IF(F10>J10,"Top of market","Within market"))
A11: Change Manager | B11: 1 | C11: 1100 | D11: 1000 | E11: 1.4 | F11: =D11*E11 | G11: =F11-D11 | H11: =IF(F11=0,0,G11/F11) | I11: 900 | J11: 1250 | K11: =IF(F11>J11*1.15,"Above market ceiling",IF(F11>J11,"Top of market","Within market"))
A12: Test Manager | B12: 0 | D12: 1000 | E12: 1.4 | F12: =D12*E12 | G12: =F12-D12 | H12: =IF(F12=0,0,G12/F12) | I12: 760 | J12: 1200 | K12: =IF(F12>J12*1.15,"Above market ceiling",IF(F12>J12,"Top of market","Within market"))
A13: Copywriter / Content Specialist | B13: 0 | D13: 600 | E13: 1.4 | F13: =D13*E13 | G13: =F13-D13 | H13: =IF(F13=0,0,G13/F13) | I13: 750 | J13: 1100 | K13: =IF(F13>J13*1.15,"Above market ceiling",IF(F13>J13,"Top of market","Within market"))
A14: Content / UX Strategist | B14: 0 | D14: 800 | E14: 1.4 | F14: =D14*E14 | G14: =F14-D14 | H14: =IF(F14=0,0,G14/F14) | I14: 800 | J14: 1140 | K14: =IF(F14>J14*1.15,"Above market ceiling",IF(F14>J14,"Top of market","Within market"))
A15: Principal — Program & Delivery Leadership (Sky) | B15: 0 | F15: 1550 | G15: =F15-D15 | H15: =IF(F15=0,0,G15/F15) | I15: 1150 | J15: 1500 | K15: =IF(F15>J15*1.15,"Above market ceiling",IF(F15>J15,"Top of market","Within market"))
A17: Market low/high = QLD/Brisbane contractor day rates (mid–senior span) from Peoplebank Aug 2025 and The Network 2025 — see Market Benchmarks sheet for the underlying rows. Guide rates are what the contractor receives; a client buying through an agency typically pays ~10–20% on top, so 'Above market ceiling' means the charge-out exceeds even the agency-billed top (market high × 1.15).
A20: Annual gross margin (whole squad)
A21: Billable days per person per year | B21: 220
A22: Gross margin per year at full utilisation | B22: =SUMPRODUCT(B7:B15,G7:G15)*B21
A23: This margin funds: PI/PL insurance, workers comp equivalents, software, accounting, tender responses, principal oversight time, payment-term gap (Vantage Meridian pays sole traders before clients pay Vantage Meridian) and profit.
A26: Legend
A27: Blue text = hardcoded input (edit freely)
A28: Yellow fill = key assumption / scenario lever
A29: Black = formula — do not overtype

Sheet Profit Model
A1: Vantage Meridian — Profit Model (annual)
A2: CONFIDENTIAL — internal only. Squad of five as per Margin Model. All overhead figures are estimates in blue — replace with real quotes as they arrive.
A4: Charge-out per squad day (all 5 billed) | B4: =SUMPRODUCT('Margin Model'!B7:B15,'Margin Model'!F7:F15)
A5: Pay per squad day (all 5 working) | B5: =SUMPRODUCT('Margin Model'!B7:B15,'Margin Model'!D7:D15)
A7: Utilisation scenario | B7: Full utilisation | C7: Realistic (85%) | D7: Slow start (70%)
A8: Utilisation % | B8: 1 | C8: 0.85 | D8: 0.7
A9: Billable days per person | B9: ='Margin Model'!$B$21*B8 | C9: ='Margin Model'!$B$21*C8 | D9: ='Margin Model'!$B$21*D8
A10: Revenue | B10: =$B$4*B9 | C10: =$B$4*C9 | D10: =$B$4*D9
A11: less Team pay (sole-trader invoices) | B11: =-$B$5*B9 | C11: =-$B$5*C9 | D11: =-$B$5*D9
A12: Gross margin | B12: =B10+B11 | C12: =C10+C11 | D12: =D10+D11
A14: Overheads (annual estimates — edit blue cells)
A15: PI ($10M) + PL ($20M) insurance | B15: 6000 | C15: =$B15 | D15: =$B15
A16: Cyber insurance | B16: 2500 | C16: =$B16 | D16: =$B16
A17: Accounting, bookkeeping & tax agent | B17: 7000 | C17: =$B17 | D17: =$B17
A18: Software & subscriptions | B18: 4000 | C18: =$B18 | D18: =$B18
A19: Legal | B19: 5000 | C19: =$B19 | D19: =$B19
A20: Marketing, website, LinkedIn | B20: 2500 | C20: =$B20 | D20: =$B20
A21: ASIC, registrations, misc | B21: 1000 | C21: =$B21 | D21: =$B21
A22: Bad debt / late payment provision (1% of revenue) | B22: =B10*$B$24 | C22: =C10*$B$24 | D22: =D10*$B$24
A23: Working-capital financing (you pay the team before clients pay you) | B23: =-B11*($B$25/52)*$B$26 | C23: =-C11*($B$25/52)*$B$26 | D23: =-D11*($B$25/52)*$B$26
A24: Provision rate for bad debt | B24: 0.01
A25: Payment gap (weeks between paying team and being paid) | B25: 4
A26: Financing rate on the float | B26: 0.1
A28: Total overheads | B28: =SUM(B15:B23) | C28: =SUM(C15:C23) | D28: =SUM(D15:D23)
A30: OPERATING PROFIT — before paying yourself, before company tax | B30: =B12-B28 | C30: =C12-C28 | D30: =D12-D28
A31: Operating margin (% of revenue) | B31: =IF(B10=0,0,B30/B10) | C31: =IF(C10=0,0,C30/C10) | D31: =IF(D10=0,0,D30/D10)
A33: Memo: company tax at 25% if profit retained in Lavelle Pty Ltd | B33: =B30*0.25 | C33: =C30*0.25 | D33: =D30*0.25
A35: What this profit still has to fund: (1) YOUR pay — by default the Principal row (Margin Model row 15, $1,550/day) has headcount 0, so your own billing is NOT in these numbers; set its headcount to 1 to include it. Running the squad still takes ~1 day/week of unbillable principal time (client management, tendering, oversight) — $55k–$65k/yr of forgone billing at your rate. (2) Anything not listed above. Not modelled, verify with your accountant: Qld payroll tax — payments to contractors under 'relevant contracts' can count as taxable wages; squad pay at full utilisation (~$880k) is under the $1.3M threshold, but adding yourself + growth could cross it. Also confirm WorkCover Qld treatment of the sole traders.
A41: Blue = estimate to replace with real quotes | Yellow = scenario lever | Green = pulled from Margin Model | Black = formula

Sheet Client Rate Card
A1: Vantage Meridian
A2: Professional Services Rate Card — effective August 2026
A3: All rates AUD per day, exclusive of GST. Valid for 90 days from issue.
A5: Role | B5: Scope of service | C5: Day rate (AUD, ex GST)
A6: Principal Consultant — Program & Delivery Leadership | B6: Program and project leadership, delivery recovery, business cases and options analysis, executive stakeholder management, vendor and RFP management, delivery assurance. | C6: ='Margin Model'!F15
A7: Developer — Junior | B7: Feature development and defect resolution under senior technical direction; unit testing, documentation, full participation in sprint ceremonies. | C7: ='Margin Model'!F7
A8: Developer — Mid-level | B8: Frontend, CRM and backend development within an established technical direction; sprint delivery, code review participation, documentation. | C8: ='Margin Model'!F8
A9: Developer — Senior | B9: Complex feature and integration delivery, technical design input, mentoring of junior and mid-level developers, production support. | C9: ='Margin Model'!F9
A10: Business Analyst | B10: Requirements elicitation and analysis, process mapping, user stories and acceptance criteria, stakeholder workshops, options and business case support. | C10: ='Margin Model'!F10
A11: Change Manager | B11: Change impact assessment, stakeholder engagement and communications, training strategy and delivery, adoption measurement. | C11: ='Margin Model'!F11
A12: Test Manager | B12: Test strategy and planning, test team coordination, defect triage and reporting, UAT management, go-live readiness assessment. | C12: ='Margin Model'!F12
A13: Copywriter / Content Specialist | B13: Web, campaign and product copy; content design and tone-of-voice application; editing, content migration and publication support within delivery programs. | C13: ='Margin Model'!F13
A14: Content / UX Strategist | B14: Content strategy and information architecture, UX research and journey mapping, content design standards, experience strategy within delivery programs. | C14: ='Margin Model'!F14
A15: Terms
A16: • Rates are inclusive of all on-costs: professional indemnity and public liability insurance, engagement management and senior principal oversight on every engagement.
A17: • Delivery is by Vantage Meridian's established practitioner network under Vantage Meridian master agreements — one contract, one invoice, no agency layering.
A18: • Team members work from client site or remotely and provide their own equipment.
A19: • Fixed-price and outcome-based pricing available on request for defined scopes.
A21: Vantage Meridian | skylavelle@vantagemeridian.com.au
A23: [Internal note — delete before sending: rate cells link to the Margin Model sheet; export this sheet as values/PDF only.]

Sheet Market Benchmarks
A1: Market Benchmarks — QLD / Brisbane
A2: Extracted 4 Aug 2026 from the three guides held in Tenders/Rates. Contract figures are day rates paid to the contractor; client-billed cost via an agency is typically ~10–20% higher.
A4: Peoplebank Salary Guide — QLD contract day rates
A5: Source: Peoplebank Salary Guide August 2025, QLD columns of the Business Applications, Developers, Testers and Project Services tables (rates are daily, AUD).
A6: Role | B6: Low ($/day) | C6: High ($/day) | E6: Note
A7: Business Analyst | B7: 900 | C7: 1100
A8: Principal / Lead BA | B8: 1000 | C8: 1250
A9: Change Manager — Organisational | B9: 900 | C9: 1250
A10: Change Lead | B10: 850 | C10: 1100
A11: Test Manager | B11: 950 | C11: 1200
A12: Test Lead | B12: 950 | C12: 1050
A13: Developer — .NET / Java | B13: 800 | C13: 1100 | E13: Same QLD band for .NET and Java
A14: Developer — Front End / Back End / Full Stack | B14: 800 | C14: 1100
A15: Web Developer | B15: 750 | C15: 1200
A16: Technical Lead | B16: 1000 | C16: 1300
A17: Project Manager — Applications | B17: 900 | C17: 1200
A18: Program Manager | B18: 1150 | C18: 1500 | E18: Principal rate benchmark
A19: Content Manager | B19: 750 | C19: 950 | E19: Copywriter benchmark
A20: Content Writer | B20: 900 | C20: 1100 | E20: Copywriter benchmark — digital/UX content skew
A21: Digital Strategist | B21: 800 | C21: 1100 | E21: Content / UX Strategist benchmark
A23: The Network — Brisbane contract day rates by experience
A24: Source: Salary Guide for 2025, The Network, Brisbane chapter (Project Services & Transformation, Software Engineering, Testing tables; contract rate per day AUD).
A25: Role | B25: 2–5 yrs ($/day) | C25: 5–10 yrs ($/day) | D25: 10+ yrs ($/day) | E25: Note
A26: Business Analyst | B26: 570–810 | C26: 810–1045 | D26: 950–1045
A27: Change Manager | B27: 715–905 | C27: 905–1045 | D27: 950–1190
A28: Organisational Change Manager | B28: 715–855 | C28: 855–1140 | D28: 950–1140
A29: Test Manager | B29: 570–715 | C29: 715–855 | D29: 760–950
A30: QA Test Manager | B30: 530–760 | C30: 685–855 | D30: 760–930
A31: Front End Developer | B31: 525–810 | C31: 760–905 | D31: 855–1140
A32: Backend Developer | B32: 525–715 | C32: 665–855 | D32: 760–950
A33: Full Stack Developer | B33: 475–715 | C33: 715–855 | D33: 855–1235
A34: Java / .NET Developer | B34: 380–620 | C34: 570–760 | D34: 760–950
A35: Project Manager | B35: 715–1000 | C35: 855–1140 | D35: 1000–1235
A36: Program Manager | B36: 1045–1285 | C36: 1285–1380 | D36: 1380–1475 | E36: Principal rate benchmark
A37: UX/UI Designer | B37: 570–905 | C37: 905–1045 | D37: 1045–1140 | E37: Content / UX Strategist benchmark
A39: Hays Salary Guide — QLD permanent salaries (context only)
A40: Source: Hays Salary Guide FY25-26, Technology chapter, QLD rows (salaries in $'000 p.a., excluding super — no contract day rates published; useful as a pay-rate sanity check only).
A41: Role | B41: Typical ($k) | C41: Range ($k) | E41: Note
A42: Business Analyst | B42: 110 | C42: 100–130
A43: Senior Business Analyst | B43: 130 | C43: 110–150
...
